Workbook

Sheet REKAP_TAHUNAN
A1: REKAPITULASI EVALUASI PERKEMBANGAN ANAK (1 TAHUN AJARAN)
A2: Nama Anak: ____________________ | Kelas: TK-A / TK-B | Tahun Ajaran: 2026/2027
A4: Bulan | B4: Rata-Rata Skor (0 - 2.0) | C4: Kategori Capaian | D4: Status Perkembangan | E4: Rekomendasi Treatment Utama
A5: Januari | B5: =IF(Januari!AJ24="", "", Januari!AJ24) -> 1.4 | C5: =IF(B5="","",IF(B5>=1.63,"BSB",IF(B5>=1.26,"BSH",IF(B5>=0.76,"MB","BB")))) -> BSH | D5: =IF(B5="","",IF(B5>=1.63,"Sangat Mandiri & Konsisten",IF(B5>=1.26,"Berkembang Sesuai Usia",IF(B5>=0.76,"Masih Butuh Bimbingan","Perlu Intervensi Khusus")))) -> Berkembang Sesuai Usia | E5: =IF(B5="","Belum Ada Data Input",IF(B5>=1.63,"Pengayaan, Tantangan Proyek Baru & Kepemimpinan",IF(B5>=1.26,"Apresiasi & Pertahankan Pembiasaan Rutin Harian",IF(B5>=0.76,"Pendampingan Personal (Scaffolding) & Komunikasi Rutin","Konseling / Evaluasi Mendalam Bersama Orang Tua")))) -> Apresiasi & Pertahankan Pembiasaan Rutin Harian
A6: Februari | B6: =IF(Februari!AG24="", "", Februari!AG24) | C6: =IF(B6="","",IF(B6>=1.63,"BSB",IF(B6>=1.26,"BSH",IF(B6>=0.76,"MB","BB")))) | D6: =IF(B6="","",IF(B6>=1.63,"Sangat Mandiri & Konsisten",IF(B6>=1.26,"Berkembang Sesuai Usia",IF(B6>=0.76,"Masih Butuh Bimbingan","Perlu Intervensi Khusus")))) | E6: =IF(B6="","Belum Ada Data Input",IF(B6>=1.63,"Pengayaan, Tantangan Proyek Baru & Kepemimpinan",IF(B6>=1.26,"Apresiasi & Pertahankan Pembiasaan Rutin Harian",IF(B6>=0.76,"Pendampingan Personal (Scaffolding) & Komunikasi Rutin","Konseling / Evaluasi Mendalam Bersama Orang Tua")))) -> Belum Ada Data Input
A7: Maret | B7: =IF(Maret!AJ24="", "", Maret!AJ24) | C7: =IF(B7="","",IF(B7>=1.63,"BSB",IF(B7>=1.26,"BSH",IF(B7>=0.76,"MB","BB")))) | D7: =IF(B7="","",IF(B7>=1.63,"Sangat Mandiri & Konsisten",IF(B7>=1.26,"Berkembang Sesuai Usia",IF(B7>=0.76,"Masih Butuh Bimbingan","Perlu Intervensi Khusus")))) | E7: =IF(B7="","Belum Ada Data Input",IF(B7>=1.63,"Pengayaan, Tantangan Proyek Baru & Kepemimpinan",IF(B7>=1.26,"Apresiasi & Pertahankan Pembiasaan Rutin Harian",IF(B7>=0.76,"Pendampingan Personal (Scaffolding) & Komunikasi Rutin","Konseling / Evaluasi Mendalam Bersama Orang Tua")))) -> Belum Ada Data Input
A8: April | B8: =IF(April!AI24="", "", April!AI24) | C8: =IF(B8="","",IF(B8>=1.63,"BSB",IF(B8>=1.26,"BSH",IF(B8>=0.76,"MB","BB")))) | D8: =IF(B8="","",IF(B8>=1.63,"Sangat Mandiri & Konsisten",IF(B8>=1.26,"Berkembang Sesuai Usia",IF(B8>=0.76,"Masih Butuh Bimbingan","Perlu Intervensi Khusus")))) | E8: =IF(B8="","Belum Ada Data Input",IF(B8>=1.63,"Pengayaan, Tantangan Proyek Baru & Kepemimpinan",IF(B8>=1.26,"Apresiasi & Pertahankan Pembiasaan Rutin Harian",IF(B8>=0.76,"Pendampingan Personal (Scaffolding) & Komunikasi Rutin","Konseling / Evaluasi Mendalam Bersama Orang Tua")))) -> Belum Ada Data Input
A9: Mei | B9: =IF(Mei!AJ24="", "", Mei!AJ24) | C9: =IF(B9="","",IF(B9>=1.63,"BSB",IF(B9>=1.26,"BSH",IF(B9>=0.76,"MB","BB")))) | D9: =IF(B9="","",IF(B9>=1.63,"Sangat Mandiri & Konsisten",IF(B9>=1.26,"Berkembang Sesuai Usia",IF(B9>=0.76,"Masih Butuh Bimbingan","Perlu Intervensi Khusus")))) | E9: =IF(B9="","Belum Ada Data Input",IF(B9>=1.63,"Pengayaan, Tantangan Proyek Baru & Kepemimpinan",IF(B9>=1.26,"Apresiasi & Pertahankan Pembiasaan Rutin Harian",IF(B9>=0.76,"Pendampingan Personal (Scaffolding) & Komunikasi Rutin","Konseling / Evaluasi Mendalam Bersama Orang Tua")))) -> Belum Ada Data Input
A10: Juni | B10: =IF(Juni!AI24="", "", Juni!AI24) | C10: =IF(B10="","",IF(B10>=1.63,"BSB",IF(B10>=1.26,"BSH",IF(B10>=0.76,"MB","BB")))) | D10: =IF(B10="","",IF(B10>=1.63,"Sangat Mandiri & Konsisten",IF(B10>=1.26,"Berkembang Sesuai Usia",IF(B10>=0.76,"Masih Butuh Bimbingan","Perlu Intervensi Khusus")))) | E10: =IF(B10="","Belum Ada Data Input",IF(B10>=1.63,"Pengayaan, Tantangan Proyek Baru & Kepemimpinan",IF(B10>=1.26,"Apresiasi & Pertahankan Pembiasaan Rutin Harian",IF(B10>=0.76,"Pendampingan Personal (Scaffolding) & Komunikasi Rutin","Konseling / Evaluasi Mendalam Bersama Orang Tua")))) -> Belum Ada Data Input
A11: Juli | B11: =IF(Juli!AJ24="", "", Juli!AJ24) | C11: =IF(B11="","",IF(B11>=1.63,"BSB",IF(B11>=1.26,"BSH",IF(B11>=0.76,"MB","BB")))) | D11: =IF(B11="","",IF(B11>=1.63,"Sangat Mandiri & Konsisten",IF(B11>=1.26,"Berkembang Sesuai Usia",IF(B11>=0.76,"Masih Butuh Bimbingan","Perlu Intervensi Khusus")))) | E11: =IF(B11="","Belum Ada Data Input",IF(B11>=1.63,"Pengayaan, Tantangan Proyek Baru & Kepemimpinan",IF(B11>=1.26,"Apresiasi & Pertahankan Pembiasaan Rutin Harian",IF(B11>=0.76,"Pendampingan Personal (Scaffolding) & Komunikasi Rutin","Konseling / Evaluasi Mendalam Bersama Orang Tua")))) -> Belum Ada Data Input
A12: Agustus | B12: =IF(Agustus!AJ24="", "", Agustus!AJ24) | C12: =IF(B12="","",IF(B12>=1.63,"BSB",IF(B12>=1.26,"BSH",IF(B12>=0.76,"MB","BB")))) | D12: =IF(B12="","",IF(B12>=1.63,"Sangat Mandiri & Konsisten",IF(B12>=1.26,"Berkembang Sesuai Usia",IF(B12>=0.76,"Masih Butuh Bimbingan","Perlu Intervensi Khusus")))) | E12: =IF(B12="","Belum Ada Data Input",IF(B12>=1.63,"Pengayaan, Tantangan Proyek Baru & Kepemimpinan",IF(B12>=1.26,"Apresiasi & Pertahankan Pembiasaan Rutin Harian",IF(B12>=0.76,"Pendampingan Personal (Scaffolding) & Komunikasi Rutin","Konseling / Evaluasi Mendalam Bersama Orang Tua")))) -> Belum Ada Data Input
A13: September | B13: =IF(September!AI24="", "", September!AI24) | C13: =IF(B13="","",IF(B13>=1.63,"BSB",IF(B13>=1.26,"BSH",IF(B13>=0.76,"MB","BB")))) | D13: =IF(B13="","",IF(B13>=1.63,"Sangat Mandiri & Konsisten",IF(B13>=1.26,"Berkembang Sesuai Usia",IF(B13>=0.76,"Masih Butuh Bimbingan","Perlu Intervensi Khusus")))) | E13: =IF(B13="","Belum Ada Data Input",IF(B13>=1.63,"Pengayaan, Tantangan Proyek Baru & Kepemimpinan",IF(B13>=1.26,"Apresiasi & Pertahankan Pembiasaan Rutin Harian",IF(B13>=0.76,"Pendampingan Personal (Scaffolding) & Komunikasi Rutin","Konseling / Evaluasi Mendalam Bersama Orang Tua")))) -> Belum Ada Data Input
A14: Oktober | B14: =IF(Oktober!AJ24="", "", Oktober!AJ24) | C14: =IF(B14="","",IF(B14>=1.63,"BSB",IF(B14>=1.26,"BSH",IF(B14>=0.76,"MB","BB")))) | D14: =IF(B14="","",IF(B14>=1.63,"Sangat Mandiri & Konsisten",IF(B14>=1.26,"Berkembang Sesuai Usia",IF(B14>=0.76,"Masih Butuh Bimbingan","Perlu Intervensi Khusus")))) | E14: =IF(B14="","Belum Ada Data Input",IF(B14>=1.63,"Pengayaan, Tantangan Proyek Baru & Kepemimpinan",IF(B14>=1.26,"Apresiasi & Pertahankan Pembiasaan Rutin Harian",IF(B14>=0.76,"Pendampingan Personal (Scaffolding) & Komunikasi Rutin","Konseling / Evaluasi Mendalam Bersama Orang Tua")))) -> Belum Ada Data Input
A15: November | B15: =IF(November!AI24="", "", November!AI24) | C15: =IF(B15="","",IF(B15>=1.63,"BSB",IF(B15>=1.26,"BSH",IF(B15>=0.76,"MB","BB")))) | D15: =IF(B15="","",IF(B15>=1.63,"Sangat Mandiri & Konsisten",IF(B15>=1.26,"Berkembang Sesuai Usia",IF(B15>=0.76,"Masih Butuh Bimbingan","Perlu Intervensi Khusus")))) | E15: =IF(B15="","Belum Ada Data Input",IF(B15>=1.63,"Pengayaan, Tantangan Proyek Baru & Kepemimpinan",IF(B15>=1.26,"Apresiasi & Pertahankan Pembiasaan Rutin Harian",IF(B15>=0.76,"Pendampingan Personal (Scaffolding) & Komunikasi Rutin","Konseling / Evaluasi Mendalam Bersama Orang Tua")))) -> Belum Ada Data Input
A16: Desember | B16: =IF(Desember!AJ24="", "", Desember!AJ24) | C16: =IF(B16="","",IF(B16>=1.63,"BSB",IF(B16>=1.26,"BSH",IF(B16>=0.76,"MB","BB")))) | D16: =IF(B16="","",IF(B16>=1.63,"Sangat Mandiri & Konsisten",IF(B16>=1.26,"Berkembang Sesuai Usia",IF(B16>=0.76,"Masih Butuh Bimbingan","Perlu Intervensi Khusus")))) | E16: =IF(B16="","Belum Ada Data Input",IF(B16>=1.63,"Pengayaan, Tantangan Proyek Baru & Kepemimpinan",IF(B16>=1.26,"Apresiasi & Pertahankan Pembiasaan Rutin Harian",IF(B16>=0.76,"Pendampingan Personal (Scaffolding) & Komunikasi Rutin","Konseling / Evaluasi Mendalam Bersama Orang Tua")))) -> Belum Ada Data Input
A17: RATA-RATA TAHUNAN | B17: =IFERROR(AVERAGE(B5:B16), "") -> 1.4 | C17: =IF(B17="","",IF(B17>=1.63,"BSB",IF(B17>=1.26,"BSH",IF(B17>=0.76,"MB","BB")))) -> BSH
A20: RUBRIK PENILAIAN & PANDUAN KLASIFIKASI TREATMENT GURU
A21: Skor Rata-Rata | B21: Kategori | C21: Arti Capaian | D21: Tindak Lanjut / Treatment Guru & Orang Tua
A22: 1.63 - 2.00 | B22: BSB | C22: Berkembang Sangat Baik | D22: Anak sangat mandiri & konsisten. Berikan proyek tantangan kepemimpinan dan pengayaan aktivitas baru.
A23: 1.26 - 1.62 | B23: BSH | C23: Berkembang Sesuai Harapan | D23: Anak berkembang sesuai usia. Pertahankan stimulasi rutin harian dan berikan pujian/apresiasi positif.
A24: 0.76 - 1.25 | B24: MB | C24: Mulai Berkembang | D24: Anak masih butuh bimbingan. Lakukan pendampingan personal (scaffolding) dan tingkatkan komunikasi rumah-sekolah.
A25: 0.00 - 0.75 | B25: BB | C25: Belum Berkembang | D25: Memerlukan intervensi khusus. Lakukan konseling/dialog mendalam bersama orang tua dan susun pendampingan terpandu.

Sheet Januari
A1: JURNAL PENILAIAN HARIAN & BULANAN AKTIVITAS ANAK TK - BULAN JANUARI
A2: Nama Anak: ____________________ | Kelas: TK-A / TK-B | Tahun Ajaran: 2026/2027
A4: Pilar Evaluasi | B4: Indikator Aktivitas Harian | C4: Panduan Skor (0, 1, 2) | D4: Tgl 1 | E4: Tgl 2 | F4: Tgl 3 | G4: Tgl 4 | H4: Tgl 5 | I4: Tgl 6 | J4: Tgl 7 | K4: Tgl 8 | L4: Tgl 9 | M4: Tgl 10 | N4: Tgl 11 | O4: Tgl 12 | P4: Tgl 13 | Q4: Tgl 14 | R4: Tgl 15 | S4: Tgl 16 | T4: Tgl 17 | U4: Tgl 18 | V4: Tgl 19 | W4: Tgl 20 | X4: Tgl 21 | Y4: Tgl 22 | Z4: Tgl 23 | AA4: Tgl 24 | AB4: Tgl 25 | AC4: Tgl 26 | AD4: Tgl 27 | AE4: Tgl 28 | AF4: Tgl 29 | AG4: Tgl 30 | AH4: Tgl 31 | AI4: Total Skor | AJ4: Rata-Rata Indikator
A5: Spiritual | B5: Shalat Subuh tepat waktu / belajar ikut tanpa drama | C5: 2: Tepat waktu/Ceria | 1: Kesiangan/Drama | 0: Belum mau | D5: 1 | AI5: =IF(COUNT(D5:AH5)>0, SUM(D5:AH5), "") -> 1 | AJ5: =IF(COUNT(D5:AH5)>0, AVERAGE(D5:AH5), "") -> 1
A6: Spiritual | B6: Shalat Dzuhur tepat waktu / mau diajak shalat berjamaah | C6: 2: Mau diajak/Ceria | 1: Diingatkan berkali-kali | 0: Belum mau | D6: 2 | AI6: =IF(COUNT(D6:AH6)>0, SUM(D6:AH6), "") -> 2 | AJ6: =IF(COUNT(D6:AH6)>0, AVERAGE(D6:AH6), "") -> 2
A7: Spiritual | B7: Shalat Ashar tepat waktu / mau diajak shalat berjamaah | C7: 2: Mau diajak/Ceria | 1: Diingatkan berkali-kali | 0: Belum mau | D7: 1 | AI7: =IF(COUNT(D7:AH7)>0, SUM(D7:AH7), "") -> 1 | AJ7: =IF(COUNT(D7:AH7)>0, AVERAGE(D7:AH7), "") -> 1
A8: Spiritual | B8: Shalat Maghrib tepat waktu / mau diajak shalat berjamaah | C8: 2: Mau diajak/Ceria | 1: Diingatkan berkali-kali | 0: Belum mau | D8: 2 | AI8: =IF(COUNT(D8:AH8)>0, SUM(D8:AH8), "") -> 2 | AJ8: =IF(COUNT(D8:AH8)>0, AVERAGE(D8:AH8), "") -> 2
A9: Spiritual | B9: Shalat Isya tepat waktu / mau diajak shalat berjamaah | C9: 2: Mau diajak/Ceria | 1: Diingatkan berkali-kali | 0: Belum mau | D9: 1 | AI9: =IF(COUNT(D9:AH9)>0, SUM(D9:AH9), "") -> 1 | AJ9: =IF(COUNT(D9:AH9)>0, AVERAGE(D9:AH9), "") -> 1
A10: Fisik & Motorik | B10: Olahraga Pagi (senam/jalan/sepeda/fisik aktif) | C10: 2: Bergerak aktif/Ceria | 1: Hanya sebentar/Kurang semangat | 0: Malas bergerak | AI10: =IF(COUNT(D10:AH10)>0, SUM(D10:AH10), "") | AJ10: =IF(COUNT(D10:AH10)>0, AVERAGE(D10:AH10), "")
A11: Fisik & Motorik | B11: Bermain Fisik Aktif Sore (bukan main gadget/HP) | C11: 2: Main luar rumah/Fisik | 1: Main di dalam rumah saja | 0: Full main HP/Gadget | AI11: =IF(COUNT(D11:AH11)>0, SUM(D11:AH11), "") | AJ11: =IF(COUNT(D11:AH11)>0, AVERAGE(D11:AH11), "")
A12: Kemandirian | B12: Bangun Tidur Pagi tanpa rewel | C12: 2: Bangun ceria & segar | 1: Merengek sebentar | 0: Mengamuk/Tantrum lama | AI12: =IF(COUNT(D12:AH12)>0, SUM(D12:AH12), "") | AJ12: =IF(COUNT(D12:AH12)>0, AVERAGE(D12:AH12), "")
A13: Kemandirian | B13: Perawatan Diri Pagi (mandi, sikat gigi, pakai baju sendiri) | C13: 2: Mandi & bersiap sendiri | 1: Dibantu setengahnya | 0: Dibantu total/Drama | AI13: =IF(COUNT(D13:AH13)>0, SUM(D13:AH13), "") | AJ13: =IF(COUNT(D13:AH13)>0, AVERAGE(D13:AH13), "")
A14: Kemandirian | B14: Sarapan Pagi dengan tertib & mandiri | C14: 2: Habis & makan sendiri sambil duduk | 1: Disuapi sebagian | 0: Disuapi total/Sambil HP | AI14: =IF(COUNT(D14:AH14)>0, SUM(D14:AH14), "") | AJ14: =IF(COUNT(D14:AH14)>0, AVERAGE(D14:AH14), "")
A15: Kemandirian | B15: Merapikan kembali mainan atau buku yang selesai digunakan | C15: 2: Inisiatif sendiri merapikan | 1: Harus disuruh berkali-kali | 0: Menolak/Ditinggal berantakan | AI15: =IF(COUNT(D15:AH15)>0, SUM(D15:AH15), "") | AJ15: =IF(COUNT(D15:AH15)>0, AVERAGE(D15:AH15), "")
A16: Kemandirian | B16: Adab Pulang Rumah (ucap salam, taruh sepatu & tas sendiri) | C16: 2: Salam & taruh barang dengan rapi | 1: Harus diingatkan | 0: Barang dilempar acak-acakan | AI16: =IF(COUNT(D16:AH16)>0, SUM(D16:AH16), "") | AJ16: =IF(COUNT(D16:AH16)>0, AVERAGE(D16:AH16), "")
A17: Kemandirian | B17: Persiapan Tidur Malam (sikat gigi & baca doa tidur) | C17: 2: Sikat gigi & doa mandiri | 1: Harus dipaksa/Dikejar dulu | 0: Langsung tidur tanpa sikat | AI17: =IF(COUNT(D17:AH17)>0, SUM(D17:AH17), "") | AJ17: =IF(COUNT(D17:AH17)>0, AVERAGE(D17:AH17), "")
A18: Adab & Sosial | B18: Penggunaan 3 Kata Sakti (Maaf, Tolong, Terima Kasih) | C18: 2: Spontan mengucapkan | 1: Ucap jika diingatkan | 0: Tidak mau mengucapkan | AI18: =IF(COUNT(D18:AH18)>0, SUM(D18:AH18), "") | AJ18: =IF(COUNT(D18:AH18)>0, AVERAGE(D18:AH18), "")
A19: Adab & Sosial | B19: Mau Berbagi di rumah (berbagi makanan/mainan ke saudara) | C19: 2: Mau berbagi dengan ceria | 1: Berbagi setelah dibujuk | 0: Pelit/Merebut mainan | AI19: =IF(COUNT(D19:AH19)>0, SUM(D19:AH19), "") | AJ19: =IF(COUNT(D19:AH19)>0, AVERAGE(D19:AH19), "")
A20: Adab & Sosial | B20: Nada Bicara & Sopan Santun | C20: 2: Sopan & suara lembut | 1: Berteriak karena gemas/kesal | 0: Membentak/Kasar | AI20: =IF(COUNT(D20:AH20)>0, SUM(D20:AH20), "") | AJ20: =IF(COUNT(D20:AH20)>0, AVERAGE(D20:AH20), "")
A21: Emosi | B21: Pengendalian Rasa Kecewa (keinginan ditolak/tidak dituruti) | C21: 2: Menangis wajar/Bisa ditenangkan | 1: Merengek lama | 0: Mengamuk/Pukul/Tantrum hebat | AI21: =IF(COUNT(D21:AH21)>0, SUM(D21:AH21), "") | AJ21: =IF(COUNT(D21:AH21)>0, AVERAGE(D21:AH21), "")
A22: Emosi | B22: Kejujuran & Tanggung Jawab | C22: 2: Jujur berani mengakui kesalahan | 1: Ragu-ragu/Takut jujur | 0: Berbohong | AI22: =IF(COUNT(D22:AH22)>0, SUM(D22:AH22), "") | AJ22: =IF(COUNT(D22:AH22)>0, AVERAGE(D22:AH22), "")
A23: TOTAL SKOR HARIAN (Max 36) | D23: =IF(COUNT(D5:D22)>0, SUM(D5:D22), "") -> 7 | E23: =IF(COUNT(E5:E22)>0, SUM(E5:E22), "") | F23: =IF(COUNT(F5:F22)>0, SUM(F5:F22), "") | G23: =IF(COUNT(G5:G22)>0, SUM(G5:G22), "") | H23: =IF(COUNT(H5:H22)>0, SUM(H5:H22), "") | I23: =IF(COUNT(I5:I22)>0, SUM(I5:I22), "") | J23: =IF(COUNT(J5:J22)>0, SUM(J5:J22), "") | K23: =IF(COUNT(K5:K22)>0, SUM(K5:K22), "") | ... AH23: =IF(COUNT(AH5:AH22)>0, SUM(AH5:AH22), "") | AI23: =IFERROR(SUM(AI5:AI22), "") -> 7
A24: RATA-RATA HARIAN (Skala 0 - 2.0) | D24: =IF(COUNT(D5:D22)>0, AVERAGE(D5:D22), "") -> 1.4 | E24: =IF(COUNT(E5:E22)>0, AVERAGE(E5:E22), "") | F24: =IF(COUNT(F5:F22)>0, AVERAGE(F5:F22), "") | G24: =IF(COUNT(G5:G22)>0, AVERAGE(G5:G22), "") | H24: =IF(COUNT(H5:H22)>0, AVERAGE(H5:H22), "") | I24: =IF(COUNT(I5:I22)>0, AVERAGE(I5:I22), "") | J24: =IF(COUNT(J5:J22)>0, AVERAGE(J5:J22), "") | K24: =IF(COUNT(K5:K22)>0, AVERAGE(K5:K22), "") | ... AH24: =IF(COUNT(AH5:AH22)>0, AVERAGE(AH5:AH22), "") | AJ24: =IFERROR(AVERAGE(D24:AH24), "") -> 1.4
A25: KLASIFIKASI CAPAIAN HARIAN | D25: =IF(D24="","",IF(D24>=1.63,"BSB",IF(D24>=1.26,"BSH",IF(D24>=0.76,"MB","BB")))) -> BSH | E25: =IF(E24="","",IF(E24>=1.63,"BSB",IF(E24>=1.26,"BSH",IF(E24>=0.76,"MB","BB")))) | F25: =IF(F24="","",IF(F24>=1.63,"BSB",IF(F24>=1.26,"BSH",IF(F24>=0.76,"MB","BB")))) | G25: =IF(G24="","",IF(G24>=1.63,"BSB",IF(G24>=1.26,"BSH",IF(G24>=0.76,"MB","BB")))) | H25: =IF(H24="","",IF(H24>=1.63,"BSB",IF(H24>=1.26,"BSH",IF(H24>=0.76,"MB","BB")))) | I25: =IF(I24="","",IF(I24>=1.63,"BSB",IF(I24>=1.26,"BSH",IF(I24>=0.76,"MB","BB")))) | J25: =IF(J24="","",IF(J24>=1.63,"BSB",IF(J24>=1.26,"BSH",IF(J24>=0.76,"MB","BB")))) | K25: =IF(K24="","",IF(K24>=1.63,"BSB",IF(K24>=1.26,"BSH",IF(K24>=0.76,"MB","BB")))) | ... AH25: =IF(AH24="","",IF(AH24>=1.63,"BSB",IF(AH24>=1.26,"BSH",IF(AH24>=0.76,"MB","BB")))) | AJ25: =IF(AJ24="","",IF(AJ24>=1.63,"BSB",IF(AJ24>=1.26,"BSH",IF(AJ24>=0.76,"MB","BB")))) -> BSH
A28: EVALUASI BULANAN & REKOMENDASI TREATMENT GURU
A29: =IF(AJ24="","Belum ada data pengisian harian.",IF(AJ24>=1.63,"[BSB - Berkembang Sangat Baik | Skor: " & TEXT(AJ24,"0.00") & "] Treatment: Anak sangat mandiri & konsisten. Berikan proyek tantangan kepemimpinan dan pengayaan aktivitas baru.",IF(AJ24>=1.26,"[BSH - Berkembang Sesuai Harapan | Skor: " & TEXT(AJ24,"0.00") & "] Treatment: Anak berkembang sesuai usia. Pertahankan stimulasi rutin harian dan berikan pujian/apresiasi positif.",IF(AJ24>=0.76,"[MB - Mulai Berkembang | Skor: " & TEXT(AJ24,"0.00") & "] Treatment: Anak masih butuh bimbingan. Lakukan pendampingan personal (scaffolding) dan tingkatkan komunikasi rumah-sekolah.","[BB - Belum Berkembang | Skor: " & TEXT(AJ24,"0.00") & "] Treatment: Memerlukan intervensi khusus. Lakukan konseling/dialog mendalam bersama orang tua dan susun pendampingan terpandu.")))) -> [BSH - Berkembang Sesuai Harapan | Skor: 1,40] Treatment: Anak berkembang sesuai usia. Pertahankan stimulasi rutin harian dan berikan pujian/apresiasi positif.

Sheet Februari
A1: JURNAL PENILAIAN HARIAN & BULANAN AKTIVITAS ANAK TK - BULAN FEBRUARI
A2: Nama Anak: ____________________ | Kelas: TK-A / TK-B | Tahun Ajaran: 2026/2027
A4: Pilar Evaluasi | B4: Indikator Aktivitas Harian | C4: Panduan Skor (0, 1, 2) | D4: Tgl 1 | E4: Tgl 2 | F4: Tgl 3 | G4: Tgl 4 | H4: Tgl 5 | I4: Tgl 6 | J4: Tgl 7 | K4: Tgl 8 | L4: Tgl 9 | M4: Tgl 10 | N4: Tgl 11 | O4: Tgl 12 | P4: Tgl 13 | Q4: Tgl 14 | R4: Tgl 15 | S4: Tgl 16 | T4: Tgl 17 | U4: Tgl 18 | V4: Tgl 19 | W4: Tgl 20 | X4: Tgl 21 | Y4: Tgl 22 | Z4: Tgl 23 | AA4: Tgl 24 | AB4: Tgl 25 | AC4: Tgl 26 | AD4: Tgl 27 | AE4: Tgl 28 | AF4: Total Skor | AG4: Rata-Rata Indikator
A5: Spiritual | B5: Shalat Subuh tepat waktu / belajar ikut tanpa drama | C5: 2: Tepat waktu/Ceria | 1: Kesiangan/Drama | 0: Belum mau | AF5: =IF(COUNT(D5:AE5)>0, SUM(D5:AE5), "") | AG5: =IF(COUNT(D5:AE5)>0, AVERAGE(D5:AE5), "")
A6: Spiritual | B6: Shalat Dzuhur tepat waktu / mau diajak shalat berjamaah | C6: 2: Mau diajak/Ceria | 1: Diingatkan berkali-kali | 0: Belum mau | AF6: =IF(COUNT(D6:AE6)>0, SUM(D6:AE6), "") | AG6: =IF(COUNT(D6:AE6)>0, AVERAGE(D6:AE6), "")
A7: Spiritual | B7: Shalat Ashar tepat waktu / mau diajak shalat berjamaah | C7: 2: Mau diajak/Ceria | 1: Diingatkan berkali-kali | 0: Belum mau | AF7: =IF(COUNT(D7:AE7)>0, SUM(D7:AE7), "") | AG7: =IF(COUNT(D7:AE7)>0, AVERAGE(D7:AE7), "")
A8: Spiritual | B8: Shalat Maghrib tepat waktu / mau diajak shalat berjamaah | C8: 2: Mau diajak/Ceria | 1: Diingatkan berkali-kali | 0: Belum mau | AF8: =IF(COUNT(D8:AE8)>0, SUM(D8:AE8), "") | AG8: =IF(COUNT(D8:AE8)>0, AVERAGE(D8:AE8), "")
A9: Spiritual | B9: Shalat Isya tepat waktu / mau diajak shalat berjamaah | C9: 2: Mau diajak/Ceria | 1: Diingatkan berkali-kali | 0: Belum mau | AF9: =IF(COUNT(D9:AE9)>0, SUM(D9:AE9), "") | AG9: =IF(COUNT(D9:AE9)>0, AVERAGE(D9:AE9), "")
A10: Fisik & Motorik | B10: Olahraga Pagi (senam/jalan/sepeda/fisik aktif) | C10: 2: Bergerak aktif/Ceria | 1: Hanya sebentar/Kurang semangat | 0: Malas bergerak | AF10: =IF(COUNT(D10:AE10)>0, SUM(D10:AE10), "") | AG10: =IF(COUNT(D10:AE10)>0, AVERAGE(D10:AE10), "")
A11: Fisik & Motorik | B11: Bermain Fisik Aktif Sore (bukan main gadget/HP) | C11: 2: Main luar rumah/Fisik | 1: Main di dalam rumah saja | 0: Full main HP/Gadget | AF11: =IF(COUNT(D11:AE11)>0, SUM(D11:AE11), "") | AG11: =IF(COUNT(D11:AE11)>0, AVERAGE(D11:AE11), "")
A12: Kemandirian | B12: Bangun Tidur Pagi tanpa rewel | C12: 2: Bangun ceria & segar | 1: Merengek sebentar | 0: Mengamuk/Tantrum lama | AF12: =IF(COUNT(D12:AE12)>0, SUM(D12:AE12), "") | AG12: =IF(COUNT(D12:AE12)>0, AVERAGE(D12:AE12), "")
A13: Kemandirian | B13: Perawatan Diri Pagi (mandi, sikat gigi, pakai baju sendiri) | C13: 2: Mandi & bersiap sendiri | 1: Dibantu setengahnya | 0: Dibantu total/Drama | AF13: =IF(COUNT(D13:AE13)>0, SUM(D13:AE13), "") | AG13: =IF(COUNT(D13:AE13)>0, AVERAGE(D13:AE13), "")
A14: Kemandirian | B14: Sarapan Pagi dengan tertib & mandiri | C14: 2: Habis & makan sendiri sambil duduk | 1: Disuapi sebagian | 0: Disuapi total/Sambil HP | AF14: =IF(COUNT(D14:AE14)>0, SUM(D14:AE14), "") | AG14: =IF(COUNT(D14:AE14)>0, AVERAGE(D14:AE14), "")
A15: Kemandirian | B15: Merapikan kembali mainan atau buku yang selesai digunakan | C15: 2: Inisiatif sendiri merapikan | 1: Harus disuruh berkali-kali | 0: Menolak/Ditinggal berantakan | AF15: =IF(COUNT(D15:AE15)>0, SUM(D15:AE15), "") | AG15: =IF(COUNT(D15:AE15)>0, AVERAGE(D15:AE15), "")
A16: Kemandirian | B16: Adab Pulang Rumah (ucap salam, taruh sepatu & tas sendiri) | C16: 2: Salam & taruh barang dengan rapi | 1: Harus diingatkan | 0: Barang dilempar acak-acakan | AF16: =IF(COUNT(D16:AE16)>0, SUM(D16:AE16), "") | AG16: =IF(COUNT(D16:AE16)>0, AVERAGE(D16:AE16), "")
... A22: Emosi | B22: Kejujuran & Tanggung Jawab | C22: 2: Jujur berani mengakui kesalahan | 1: Ragu-ragu/Takut jujur | 0: Berbohong | AF22: =IF(COUNT(D22:AE22)>0, SUM(D22:AE22), "") | AG22: =IF(COUNT(D22:AE22)>0, AVERAGE(D22:AE22), "")
A23: TOTAL SKOR HARIAN (Max 36) | D23: =IF(COUNT(D5:D22)>0, SUM(D5:D22), "") | E23: =IF(COUNT(E5:E22)>0, SUM(E5:E22), "") | F23: =IF(COUNT(F5:F22)>0, SUM(F5:F22), "") | G23: =IF(COUNT(G5:G22)>0, SUM(G5:G22), "") | H23: =IF(COUNT(H5:H22)>0, SUM(H5:H22), "") | I23: =IF(COUNT(I5:I22)>0, SUM(I5:I22), "") | J23: =IF(COUNT(J5:J22)>0, SUM(J5:J22), "") | K23: =IF(COUNT(K5:K22)>0, SUM(K5:K22), "") | ... AE23: =IF(COUNT(AE5:AE22)>0, SUM(AE5:AE22), "") | AF23: =IFERROR(SUM(AF5:AF22), "") -> 0
A24: RATA-RATA HARIAN (Skala 0 - 2.0) | D24: =IF(COUNT(D5:D22)>0, AVERAGE(D5:D22), "") | E24: =IF(COUNT(E5:E22)>0, AVERAGE(E5:E22), "") | F24: =IF(COUNT(F5:F22)>0, AVERAGE(F5:F22), "") | G24: =IF(COUNT(G5:G22)>0, AVERAGE(G5:G22), "") | H24: =IF(COUNT(H5:H22)>0, AVERAGE(H5:H22), "") | I24: =IF(COUNT(I5:I22)>0, AVERAGE(I5:I22), "") | J24: =IF(COUNT(J5:J22)>0, AVERAGE(J5:J22), "") | K24: =IF(COUNT(K5:K22)>0, AVERAGE(K5:K22), "") | ... AE24: =IF(COUNT(AE5:AE22)>0, AVERAGE(AE5:AE22), "") | AG24: =IFERROR(AVERAGE(D24:AE24), "")
A25: KLASIFIKASI CAPAIAN HARIAN | D25: =IF(D24="","",IF(D24>=1.63,"BSB",IF(D24>=1.26,"BSH",IF(D24>=0.76,"MB","BB")))) | E25: =IF(E24="","",IF(E24>=1.63,"BSB",IF(E24>=1.26,"BSH",IF(E24>=0.76,"MB","BB")))) | F25: =IF(F24="","",IF(F24>=1.63,"BSB",IF(F24>=1.26,"BSH",IF(F24>=0.76,"MB","BB")))) | G25: =IF(G24="","",IF(G24>=1.63,"BSB",IF(G24>=1.26,"BSH",IF(G24>=0.76,"MB","BB")))) | H25: =IF(H24="","",IF(H24>=1.63,"BSB",IF(H24>=1.26,"BSH",IF(H24>=0.76,"MB","BB")))) | I25: =IF(I24="","",IF(I24>=1.63,"BSB",IF(I24>=1.26,"BSH",IF(I24>=0.76,"MB","BB")))) | J25: =IF(J24="","",IF(J24>=1.63,"BSB",IF(J24>=1.26,"BSH",IF(J24>=0.76,"MB","BB")))) | K25: =IF(K24="","",IF(K24>=1.63,"BSB",IF(K24>=1.26,"BSH",IF(K24>=0.76,"MB","BB")))) | ... AE25: =IF(AE24="","",IF(AE24>=1.63,"BSB",IF(AE24>=1.26,"BSH",IF(AE24>=0.76,"MB","BB")))) | AG25: =IF(AG24="","",IF(AG24>=1.63,"BSB",IF(AG24>=1.26,"BSH",IF(AG24>=0.76,"MB","BB"))))
A28: EVALUASI BULANAN & REKOMENDASI TREATMENT GURU
A29: =IF(AG24="","Belum ada data pengisian harian.",IF(AG24>=1.63,"[BSB - Berkembang Sangat Baik | Skor: " & TEXT(AG24,"0.00") & "] Treatment: Anak sangat mandiri & konsisten. Berikan proyek tantangan kepemimpinan dan pengayaan aktivitas baru.",IF(AG24>=1.26,"[BSH - Berkembang Sesuai Harapan | Skor: " & TEXT(AG24,"0.00") & "] Treatment: Anak berkembang sesuai usia. Pertahankan stimulasi rutin harian dan berikan pujian/apresiasi positif.",IF(AG24>=0.76,"[MB - Mulai Berkembang | Skor: " & TEXT(AG24,"0.00") & "] Treatment: Anak masih butuh bimbingan. Lakukan pendampingan personal (scaffolding) dan tingkatkan komunikasi rumah-sekolah.","[BB - Belum Berkembang | Skor: " & TEXT(AG24,"0.00") & "] Treatment: Memerlukan intervensi khusus. Lakukan konseling/dialog mendalam bersama orang tua dan susun pendampingan terpandu.")))) -> Belum ada data pengisian harian.

Sheet Maret
A1: JURNAL PENILAIAN HARIAN & BULANAN AKTIVITAS ANAK TK - BULAN MARET
A2: Nama Anak: ____________________ | Kelas: TK-A / TK-B | Tahun Ajaran: 2026/2027
A4: Pilar Evaluasi | B4: Indikator Aktivitas Harian | C4: Panduan Skor (0, 1, 2) | D4: Tgl 1 | E4: Tgl 2 | F4: Tgl 3 | G4: Tgl 4 | H4: Tgl 5 | I4: Tgl 6 | J4: Tgl 7 | K4: Tgl 8 | L4: Tgl 9 | M4: Tgl 10 | N4: Tgl 11 | O4: Tgl 12 | P4: Tgl 13 | Q4: Tgl 14 | R4: Tgl 15 | S4: Tgl 16 | T4: Tgl 17 | U4: Tgl 18 | V4: Tgl 19 | W4: Tgl 20 | X4: Tgl 21 | Y4: Tgl 22 | Z4: Tgl 23 | AA4: Tgl 24 | AB4: Tgl 25 | AC4: Tgl 26 | AD4: Tgl 27 | AE4: Tgl 28 | AF4: Tgl 29 | AG4: Tgl 30 | AH4: Tgl 31 | AI4: Total Skor | AJ4: Rata-Rata Indikator
A5: Spiritual | B5: Shalat Subuh tepat waktu / belajar ikut tanpa drama | C5: 2: Tepat waktu/Ceria | 1: Kesiangan/Drama | 0: Belum mau | AI5: =IF(COUNT(D5:AH5)>0, SUM(D5:AH5), "") | AJ5: =IF(COUNT(D5:AH5)>0, AVERAGE(D5:AH5), "")
A6: Spiritual | B6: Shalat Dzuhur tepat waktu / mau diajak shalat berjamaah | C6: 2: Mau diajak/Ceria | 1: Diingatkan berkali-kali | 0: Belum mau | AI6: =IF(COUNT(D6:AH6)>0, SUM(D6:AH6), "") | AJ6: =IF(COUNT(D6:AH6)>0, AVERAGE(D6:AH6), "")
A7: Spiritual | B7: Shalat Ashar tepat waktu / mau diajak shalat berjamaah | C7: 2: Mau diajak/Ceria | 1: Diingatkan berkali-kali | 0: Belum mau | AI7: =IF(COUNT(D7:AH7)>0, SUM(D7:AH7), "") | AJ7: =IF(COUNT(D7:AH7)>0, AVERAGE(D7:AH7), "")
A8: Spiritual | B8: Shalat Maghrib tepat waktu / mau diajak shalat berjamaah | C8: 2: Mau diajak/Ceria | 1: Diingatkan berkali-kali | 0: Belum mau | AI8: =IF(COUNT(D8:AH8)>0, SUM(D8:AH8), "") | AJ8: =IF(COUNT(D8:AH8)>0, AVERAGE(D8:AH8), "")
A9: Spiritual | B9: Shalat Isya tepat waktu / mau diajak shalat berjamaah | C9: 2: Mau diajak/Ceria | 1: Diingatkan berkali-kali | 0: Belum mau | AI9: =IF(COUNT(D9:AH9)>0, SUM(D9:AH9), "") | AJ9: =IF(COUNT(D9:AH9)>0, AVERAGE(D9:AH9), "")
A10: Fisik & Motorik | B10: Olahraga Pagi (senam/jalan/sepeda/fisik aktif) | C10: 2: Bergerak aktif/Ceria | 1: Hanya sebentar/Kurang semangat | 0: Malas bergerak | AI10: =IF(COUNT(D10:AH10)>0, SUM(D10:AH10), "") | AJ10: =IF(COUNT(D10:AH10)>0, AVERAGE(D10:AH10), "")
A11: Fisik & Motorik | B11: Bermain Fisik Aktif Sore (bukan main gadget/HP) | C11: 2: Main luar rumah/Fisik | 1: Main di dalam rumah saja | 0: Full main HP/Gadget | AI11: =IF(COUNT(D11:AH11)>0, SUM(D11:AH11), "") | AJ11: =IF(COUNT(D11:AH11)>0, AVERAGE(D11:AH11), "")
A12: Kemandirian | B12: Bangun Tidur Pagi tanpa rewel | C12: 2: Bangun ceria & segar | 1: Merengek sebentar | 0: Mengamuk/Tantrum lama | AI12: =IF(COUNT(D12:AH12)>0, SUM(D12:AH12), "") | AJ12: =IF(COUNT(D12:AH12)>0, AVERAGE(D12:AH12), "")
A13: Kemandirian | B13: Perawatan Diri Pagi (mandi, sikat gigi, pakai baju sendiri) | C13: 2: Mandi & bersiap sendiri | 1: Dibantu setengahnya | 0: Dibantu total/Drama | AI13: =IF(COUNT(D13:AH13)>0, SUM(D13:AH13), "") | AJ13: =IF(COUNT(D13:AH13)>0, AVERAGE(D13:AH13), "")
A14: Kemandirian | B14: Sarapan Pagi dengan tertib & mandiri | C14: 2: Habis & makan sendiri sambil duduk | 1: Disuapi sebagian | 0: Disuapi total/Sambil HP | AI14: =IF(COUNT(D14:AH14)>0, SUM(D14:AH14), "") | AJ14: =IF(COUNT(D14:AH14)>0, AVERAGE(D14:AH14), "")
A15: Kemandirian | B15: Merapikan kembali mainan atau buku yang selesai digunakan | C15: 2: Inisiatif sendiri merapikan | 1: Harus disuruh berkali-kali | 0: Menolak/Ditinggal berantakan | AI15: =IF(COUNT(D15:AH15)>0, SUM(D15:AH15), "") | AJ15: =IF(COUNT(D15:AH15)>0, AVERAGE(D15:AH15), "")
A16: Kemandirian | B16: Adab Pulang Rumah (ucap salam, taruh sepatu & tas sendiri) | C16: 2: Salam & taruh barang dengan rapi | 1: Harus diingatkan | 0: Barang dilempar acak-acakan | AI16: =IF(COUNT(D16:AH16)>0, SUM(D16:AH16), "") | AJ16: =IF(COUNT(D16:AH16)>0, AVERAGE(D16:AH16), "")
... A22: Emosi | B22: Kejujuran & Tanggung Jawab | C22: 2: Jujur berani mengakui kesalahan | 1: Ragu-ragu/Takut jujur | 0: Berbohong | AI22: =IF(COUNT(D22:AH22)>0, SUM(D22:AH22), "") | AJ22: =IF(COUNT(D22:AH22)>0, AVERAGE(D22:AH22), "")
A23: TOTAL SKOR HARIAN (Max 36) | D23: =IF(COUNT(D5:D22)>0, SUM(D5:D22), "") | E23: =IF(COUNT(E5:E22)>0, SUM(E5:E22), "") | F23: =IF(COUNT(F5:F22)>0, SUM(F5:F22), "") | G23: =IF(COUNT(G5:G22)>0, SUM(G5:G22), "") | H23: =IF(COUNT(H5:H22)>0, SUM(H5:H22), "") | I23: =IF(COUNT(I5:I22)>0, SUM(I5:I22), "") | J23: =IF(COUNT(J5:J22)>0, SUM(J5:J22), "") | K23: =IF(COUNT(K5:K22)>0, SUM(K5:K22), "") | ... AH23: =IF(COUNT(AH5:AH22)>0, SUM(AH5:AH22), "") | AI23: =IFERROR(SUM(AI5:AI22), "") -> 0
A24: RATA-RATA HARIAN (Skala 0 - 2.0) | D24: =IF(COUNT(D5:D22)>0, AVERAGE(D5:D22), "") | E24: =IF(COUNT(E5:E22)>0, AVERAGE(E5:E22), "") | F24: =IF(COUNT(F5:F22)>0, AVERAGE(F5:F22), "") | G24: =IF(COUNT(G5:G22)>0, AVERAGE(G5:G22), "") | H24: =IF(COUNT(H5:H22)>0, AVERAGE(H5:H22), "") | I24: =IF(COUNT(I5:I22)>0, AVERAGE(I5:I22), "") | J24: =IF(COUNT(J5:J22)>0, AVERAGE(J5:J22), "") | K24: =IF(COUNT(K5:K22)>0, AVERAGE(K5:K22), "") | ... AH24: =IF(COUNT(AH5:AH22)>0, AVERAGE(AH5:AH22), "") | AJ24: =IFERROR(AVERAGE(D24:AH24), "")
A25: KLASIFIKASI CAPAIAN HARIAN | D25: =IF(D24="","",IF(D24>=1.63,"BSB",IF(D24>=1.26,"BSH",IF(D24>=0.76,"MB","BB")))) | E25: =IF(E24="","",IF(E24>=1.63,"BSB",IF(E24>=1.26,"BSH",IF(E24>=0.76,"MB","BB")))) | F25: =IF(F24="","",IF(F24>=1.63,"BSB",IF(F24>=1.26,"BSH",IF(F24>=0.76,"MB","BB")))) | G25: =IF(G24="","",IF(G24>=1.63,"BSB",IF(G24>=1.26,"BSH",IF(G24>=0.76,"MB","BB")))) | H25: =IF(H24="","",IF(H24>=1.63,"BSB",IF(H24>=1.26,"BSH",IF(H24>=0.76,"MB","BB")))) | I25: =IF(I24="","",IF(I24>=1.63,"BSB",IF(I24>=1.26,"BSH",IF(I24>=0.76,"MB","BB")))) | J25: =IF(J24="","",IF(J24>=1.63,"BSB",IF(J24>=1.26,"BSH",IF(J24>=0.76,"MB","BB")))) | K25: =IF(K24="","",IF(K24>=1.63,"BSB",IF(K24>=1.26,"BSH",IF(K24>=0.76,"MB","BB")))) | ... AH25: =IF(AH24="","",IF(AH24>=1.63,"BSB",IF(AH24>=1.26,"BSH",IF(AH24>=0.76,"MB","BB")))) | AJ25: =IF(AJ24="","",IF(AJ24>=1.63,"BSB",IF(AJ24>=1.26,"BSH",IF(AJ24>=0.76,"MB","BB"))))
A28: EVALUASI BULANAN & REKOMENDASI TREATMENT GURU
A29: =IF(AJ24="","Belum ada data pengisian harian.",IF(AJ24>=1.63,"[BSB - Berkembang Sangat Baik | Skor: " & TEXT(AJ24,"0.00") & "] Treatment: Anak sangat mandiri & konsisten. Berikan proyek tantangan kepemimpinan dan pengayaan aktivitas baru.",IF(AJ24>=1.26,"[BSH - Berkembang Sesuai Harapan | Skor: " & TEXT(AJ24,"0.00") & "] Treatment: Anak berkembang sesuai usia. Pertahankan stimulasi rutin harian dan berikan pujian/apresiasi positif.",IF(AJ24>=0.76,"[MB - Mulai Berkembang | Skor: " & TEXT(AJ24,"0.00") & "] Treatment: Anak masih butuh bimbingan. Lakukan pendampingan personal (scaffolding) dan tingkatkan komunikasi rumah-sekolah.","[BB - Belum Berkembang | Skor: " & TEXT(AJ24,"0.00") & "] Treatment: Memerlukan intervensi khusus. Lakukan konseling/dialog mendalam bersama orang tua dan susun pendampingan terpandu.")))) -> Belum ada data pengisian harian.

Sheet April
A1: JURNAL PENILAIAN HARIAN & BULANAN AKTIVITAS ANAK TK - BULAN APRIL
A2: Nama Anak: ____________________ | Kelas: TK-A / TK-B | Tahun Ajaran: 2026/2027
A4: Pilar Evaluasi | B4: Indikator Aktivitas Harian | C4: Panduan Skor (0, 1, 2) | D4: Tgl 1 | E4: Tgl 2 | F4: Tgl 3 | G4: Tgl 4 | H4: Tgl 5 | I4: Tgl 6 | J4: Tgl 7 | K4: Tgl 8 | L4: Tgl 9 | M4: Tgl 10 | N4: Tgl 11 | O4: Tgl 12 | P4: Tgl 13 | Q4: Tgl 14 | R4: Tgl 15 | S4: Tgl 16 | T4: Tgl 17 | U4: Tgl 18 | V4: Tgl 19 | W4: Tgl 20 | X4: Tgl 21 | Y4: Tgl 22 | Z4: Tgl 23 | AA4: Tgl 24 | AB4: Tgl 25 | AC4: Tgl 26 | AD4: Tgl 27 | AE4: Tgl 28 | AF4: Tgl 29 | AG4: Tgl 30 | AH4: Total Skor | AI4: Rata-Rata Indikator
A5: Spiritual | B5: Shalat Subuh tepat waktu / belajar ikut tanpa drama | C5: 2: Tepat waktu/Ceria | 1: Kesiangan/Drama | 0: Belum mau | AH5: =IF(COUNT(D5:AG5)>0, SUM(D5:AG5), "") | AI5: =IF(COUNT(D5:AG5)>0, AVERAGE(D5:AG5), "")
A6: Spiritual | B6: Shalat Dzuhur tepat waktu / mau diajak shalat berjamaah | C6: 2: Mau diajak/Ceria | 1: Diingatkan berkali-kali | 0: Belum mau | AH6: =IF(COUNT(D6:AG6)>0, SUM(D6:AG6), "") | AI6: =IF(COUNT(D6:AG6)>0, AVERAGE(D6:AG6), "")
A7: Spiritual | B7: Shalat Ashar tepat waktu / mau diajak shalat berjamaah | C7: 2: Mau diajak/Ceria | 1: Diingatkan berkali-kali | 0: Belum mau | AH7: =IF(COUNT(D7:AG7)>0, SUM(D7:AG7), "") | AI7: =IF(COUNT(D7:AG7)>0, AVERAGE(D7:AG7), "")
A8: Spiritual | B8: Shalat Maghrib tepat waktu / mau diajak shalat berjamaah | C8: 2: Mau diajak/Ceria | 1: Diingatkan berkali-kali | 0: Belum mau | AH8: =IF(COUNT(D8:AG8)>0, SUM(D8:AG8), "") | AI8: =IF(COUNT(D8:AG8)>0, AVERAGE(D8:AG8), "")
A9: Spiritual | B9: Shalat Isya tepat waktu / mau diajak shalat berjamaah | C9: 2: Mau diajak/Ceria | 1: Diingatkan berkali-kali | 0: Belum mau | AH9: =IF(COUNT(D9:AG9)>0, SUM(D9:AG9), "") | AI9: =IF(COUNT(D9:AG9)>0, AVERAGE(D9:AG9), "")
A10: Fisik & Motorik | B10: Olahraga Pagi (senam/jalan/sepeda/fisik aktif) | C10: 2: Bergerak aktif/Ceria | 1: Hanya sebentar/Kurang semangat | 0: Malas bergerak | AH10: =IF(COUNT(D10:AG10)>0, SUM(D10:AG10), "") | AI10: =IF(COUNT(D10:AG10)>0, AVERAGE(D10:AG10), "")
A11: Fisik & Motorik | B11: Bermain Fisik Aktif Sore (bukan main gadget/HP) | C11: 2: Main luar rumah/Fisik | 1: Main di dalam rumah saja | 0: Full main HP/Gadget | AH11: =IF(COUNT(D11:AG11)>0, SUM(D11:AG11), "") | AI11: =IF(COUNT(D11:AG11)>0, AVERAGE(D11:AG11), "")
A12: Kemandirian | B12: Bangun Tidur Pagi tanpa rewel | C12: 2: Bangun ceria & segar | 1: Merengek sebentar | 0: Mengamuk/Tantrum lama | AH12: =IF(COUNT(D12:AG12)>0, SUM(D12:AG12), "") | AI12: =IF(COUNT(D12:AG12)>0, AVERAGE(D12:AG12), "")
A13: Kemandirian | B13: Perawatan Diri Pagi (mandi, sikat gigi, pakai baju sendiri) | C13: 2: Mandi & bersiap sendiri | 1: Dibantu setengahnya | 0: Dibantu total/Drama | AH13: =IF(COUNT(D13:AG13)>0, SUM(D13:AG13), "") | AI13: =IF(COUNT(D13:AG13)>0, AVERAGE(D13:AG13), "")
A14: Kemandirian | B14: Sarapan Pagi dengan tertib & mandiri | C14: 2: Habis & makan sendiri sambil duduk | 1: Disuapi sebagian | 0: Disuapi total/Sambil HP | AH14: =IF(COUNT(D14:AG14)>0, SUM(D14:AG14), "") | AI14: =IF(COUNT(D14:AG14)>0, AVERAGE(D14:AG14), "")
A15: Kemandirian | B15: Merapikan kembali mainan atau buku yang selesai digunakan | C15: 2: Inisiatif sendiri merapikan | 1: Harus disuruh berkali-kali | 0: Menolak/Ditinggal berantakan | AH15: =IF(COUNT(D15:AG15)>0, SUM(D15:AG15), "") | AI15: =IF(COUNT(D15:AG15)>0, AVERAGE(D15:AG15), "")
A16: Kemandirian | B16: Adab Pulang Rumah (ucap salam, taruh sepatu & tas sendiri) | C16: 2: Salam & taruh barang dengan rapi | 1: Harus diingatkan | 0: Barang dilempar acak-acakan | AH16: =IF(COUNT(D16:AG16)>0, SUM(D16:AG16), "") | AI16: =IF(COUNT(D16:AG16)>0, AVERAGE(D16:AG16), "")
... A22: Emosi | B22: Kejujuran & Tanggung Jawab | C22: 2: Jujur berani mengakui kesalahan | 1: Ragu-ragu/Takut jujur | 0: Berbohong | AH22: =IF(COUNT(D22:AG22)>0, SUM(D22:AG22), "") | AI22: =IF(COUNT(D22:AG22)>0, AVERAGE(D22:AG22), "")
A23: TOTAL SKOR HARIAN (Max 36) | D23: =IF(COUNT(D5:D22)>0, SUM(D5:D22), "") | E23: =IF(COUNT(E5:E22)>0, SUM(E5:E22), "") | F23: =IF(COUNT(F5:F22)>0, SUM(F5:F22), "") | G23: =IF(COUNT(G5:G22)>0, SUM(G5:G22), "") | H23: =IF(COUNT(H5:H22)>0, SUM(H5:H22), "") | I23: =IF(COUNT(I5:I22)>0, SUM(I5:I22), "") | J23: =IF(COUNT(J5:J22)>0, SUM(J5:J22), "") | K23: =IF(COUNT(K5:K22)>0, SUM(K5:K22), "") | ... AG23: =IF(COUNT(AG5:AG22)>0, SUM(AG5:AG22), "") | AH23: =IFERROR(SUM(AH5:AH22), "") -> 0
A24: RATA-RATA HARIAN (Skala 0 - 2.0) | D24: =IF(COUNT(D5:D22)>0, AVERAGE(D5:D22), "") | E24: =IF(COUNT(E5:E22)>0, AVERAGE(E5:E22), "") | F24: =IF(COUNT(F5:F22)>0, AVERAGE(F5:F22), "") | G24: =IF(COUNT(G5:G22)>0, AVERAGE(G5:G22), "") | H24: =IF(COUNT(H5:H22)>0, AVERAGE(H5:H22), "") | I24: =IF(COUNT(I5:I22)>0, AVERAGE(I5:I22), "") | J24: =IF(COUNT(J5:J22)>0, AVERAGE(J5:J22), "") | K24: =IF(COUNT(K5:K22)>0, AVERAGE(K5:K22), "") | ... AG24: =IF(COUNT(AG5:AG22)>0, AVERAGE(AG5:AG22), "") | AI24: =IFERROR(AVERAGE(D24:AG24), "")
A25: KLASIFIKASI CAPAIAN HARIAN | D25: =IF(D24="","",IF(D24>=1.63,"BSB",IF(D24>=1.26,"BSH",IF(D24>=0.76,"MB","BB")))) | E25: =IF(E24="","",IF(E24>=1.63,"BSB",IF(E24>=1.26,"BSH",IF(E24>=0.76,"MB","BB")))) | F25: =IF(F24="","",IF(F24>=1.63,"BSB",IF(F24>=1.26,"BSH",IF(F24>=0.76,"MB","BB")))) | G25: =IF(G24="","",IF(G24>=1.63,"BSB",IF(G24>=1.26,"BSH",IF(G24>=0.76,"MB","BB")))) | H25: =IF(H24="","",IF(H24>=1.63,"BSB",IF(H24>=1.26,"BSH",IF(H24>=0.76,"MB","BB")))) | I25: =IF(I24="","",IF(I24>=1.63,"BSB",IF(I24>=1.26,"BSH",IF(I24>=0.76,"MB","BB")))) | J25: =IF(J24="","",IF(J24>=1.63,"BSB",IF(J24>=1.26,"BSH",IF(J24>=0.76,"MB","BB")))) | K25: =IF(K24="","",IF(K24>=1.63,"BSB",IF(K24>=1.26,"BSH",IF(K24>=0.76,"MB","BB")))) | ... AG25: =IF(AG24="","",IF(AG24>=1.63,"BSB",IF(AG24>=1.26,"BSH",IF(AG24>=0.76,"MB","BB")))) | AI25: =IF(AI24="","",IF(AI24>=1.63,"BSB",IF(AI24>=1.26,"BSH",IF(AI24>=0.76,"MB","BB"))))
A28: EVALUASI BULANAN & REKOMENDASI TREATMENT GURU
A29: =IF(AI24="","Belum ada data pengisian harian.",IF(AI24>=1.63,"[BSB - Berkembang Sangat Baik | Skor: " & TEXT(AI24,"0.00") & "] Treatment: Anak sangat mandiri & konsisten. Berikan proyek tantangan kepemimpinan dan pengayaan aktivitas baru.",IF(AI24>=1.26,"[BSH - Berkembang Sesuai Harapan | Skor: " & TEXT(AI24,"0.00") & "] Treatment: Anak berkembang sesuai usia. Pertahankan stimulasi rutin harian dan berikan pujian/apresiasi positif.",IF(AI24>=0.76,"[MB - Mulai Berkembang | Skor: " & TEXT(AI24,"0.00") & "] Treatment: Anak masih butuh bimbingan. Lakukan pendampingan personal (scaffolding) dan tingkatkan komunikasi rumah-sekolah.","[BB - Belum Berkembang | Skor: " & TEXT(AI24,"0.00") & "] Treatment: Memerlukan intervensi khusus. Lakukan konseling/dialog mendalam bersama orang tua dan susun pendampingan terpandu.")))) -> Belum ada data pengisian harian.

Sheet Mei
A1: JURNAL PENILAIAN HARIAN & BULANAN AKTIVITAS ANAK TK - BULAN MEI
A2: Nama Anak: ____________________ | Kelas: TK-A / TK-B | Tahun Ajaran: 2026/2027
A4: Pilar Evaluasi | B4: Indikator Aktivitas Harian | C4: Panduan Skor (0, 1, 2) | D4: Tgl 1 | E4: Tgl 2 | F4: Tgl 3 | G4: Tgl 4 | H4: Tgl 5 | I4: Tgl 6 | J4: Tgl 7 | K4: Tgl 8 | L4: Tgl 9 | M4: Tgl 10 | N4: Tgl 11 | O4: Tgl 12 | P4: Tgl 13 | Q4: Tgl 14 | R4: Tgl 15 | S4: Tgl 16 | T4: Tgl 17 | U4: Tgl 18 | V4: Tgl 19 | W4: Tgl 20 | X4: Tgl 21 | Y4: Tgl 22 | Z4: Tgl 23 | AA4: Tgl 24 | AB4: Tgl 25 | AC4: Tgl 26 | AD4: Tgl 27 | AE4: Tgl 28 | AF4: Tgl 29 | AG4: Tgl 30 | AH4: Tgl 31 | AI4: Total Skor | AJ4: Rata-Rata Indikator
A5: Spiritual | B5: Shalat Subuh tepat waktu / belajar ikut tanpa drama | C5: 2: Tepat waktu/Ceria | 1: Kesiangan/Drama | 0: Belum mau | AI5: =IF(COUNT(D5:AH5)>0, SUM(D5:AH5), "") | AJ5: =IF(COUNT(D5:AH5)>0, AVERAGE(D5:AH5), "")
A6: Spiritual | B6: Shalat Dzuhur tepat waktu / mau diajak shalat berjamaah | C6: 2: Mau diajak/Ceria | 1: Diingatkan berkali-kali | 0: Belum mau | AI6: =IF(COUNT(D6:AH6)>0, SUM(D6:AH6), "") | AJ6: =IF(COUNT(D6:AH6)>0, AVERAGE(D6:AH6), "")
A7: Spiritual | B7: Shalat Ashar tepat waktu / mau diajak shalat berjamaah | C7: 2: Mau diajak/Ceria | 1: Diingatkan berkali-kali | 0: Belum mau | AI7: =IF(COUNT(D7:AH7)>0, SUM(D7:AH7), "") | AJ7: =IF(COUNT(D7:AH7)>0, AVERAGE(D7:AH7), "")
A8: Spiritual | B8: Shalat Maghrib tepat waktu / mau diajak shalat berjamaah | C8: 2: Mau diajak/Ceria | 1: Diingatkan berkali-kali | 0: Belum mau | AI8: =IF(COUNT(D8:AH8)>0, SUM(D8:AH8), "") | AJ8: =IF(COUNT(D8:AH8)>0, AVERAGE(D8:AH8), "")
A9: Spiritual | B9: Shalat Isya tepat waktu / mau diajak shalat berjamaah | C9: 2: Mau diajak/Ceria | 1: Diingatkan berkali-kali | 0: Belum mau | AI9: =IF(COUNT(D9:AH9)>0, SUM(D9:AH9), "") | AJ9: =IF(COUNT(D9:AH9)>0, AVERAGE(D9:AH9), "")
A10: Fisik & Motorik | B10: Olahraga Pagi (senam/jalan/sepeda/fisik aktif) | C10: 2: Bergerak aktif/Ceria | 1: Hanya sebentar/Kurang semangat | 0: Malas bergerak | AI10: =IF(COUNT(D10:AH10)>0, SUM(D10:AH10), "") | AJ10: =IF(COUNT(D10:AH10)>0, AVERAGE(D10:AH10), "")
A11: Fisik & Motorik | B11: Bermain Fisik Aktif Sore (bukan main gadget/HP) | C11: 2: Main luar rumah/Fisik | 1: Main di dalam rumah saja | 0: Full main HP/Gadget | AI11: =IF(COUNT(D11:AH11)>0, SUM(D11:AH11), "") | AJ11: =IF(COUNT(D11:AH11)>0, AVERAGE(D11:AH11), "")
A12: Kemandirian | B12: Bangun Tidur Pagi tanpa rewel | C12: 2: Bangun ceria & segar | 1: Merengek sebentar | 0: Mengamuk/Tantrum lama | AI12: =IF(COUNT(D12:AH12)>0, SUM(D12:AH12), "") | AJ12: =IF(COUNT(D12:AH12)>0, AVERAGE(D12:AH12), "")
A13: Kemandirian | B13: Perawatan Diri Pagi (mandi, sikat gigi, pakai baju sendiri) | C13: 2: Mandi & bersiap sendiri | 1: Dibantu setengahnya | 0: Dibantu total/Drama | AI13: =IF(COUNT(D13:AH13)>0, SUM(D13:AH13), "") | AJ13: =IF(COUNT(D13:AH13)>0, AVERAGE(D13:AH13), "")
A14: Kemandirian | B14: Sarapan Pagi dengan tertib & mandiri | C14: 2: Habis & makan sendiri sambil duduk | 1: Disuapi sebagian | 0: Disuapi total/Sambil HP | AI14: =IF(COUNT(D14:AH14)>0, SUM(D14:AH14), "") | AJ14: =IF(COUNT(D14:AH14)>0, AVERAGE(D14:AH14), "")
A15: Kemandirian | B15: Merapikan kembali mainan atau buku yang selesai digunakan | C15: 2: Inisiatif sendiri merapikan | 1: Harus disuruh berkali-kali | 0: Menolak/Ditinggal berantakan | AI15: =IF(COUNT(D15:AH15)>0, SUM(D15:AH15), "") | AJ15: =IF(COUNT(D15:AH15)>0, AVERAGE(D15:AH15), "")
A16: Kemandirian | B16: Adab Pulang Rumah (ucap salam, taruh sepatu & tas sendiri) | C16: 2: Salam & taruh barang dengan rapi | 1: Harus diingatkan | 0: Barang dilempar acak-acakan | AI16: =IF(COUNT(D16:AH16)>0, SUM(D16:AH16), "") | AJ16: =IF(COUNT(D16:AH16)>0, AVERAGE(D16:AH16), "")
... A22: Emosi | B22: Kejujuran & Tanggung Jawab | C22: 2: Jujur berani mengakui kesalahan | 1: Ragu-ragu/Takut jujur | 0: Berbohong | AI22: =IF(COUNT(D22:AH22)>0, SUM(D22:AH22), "") | AJ22: =IF(COUNT(D22:AH22)>0, AVERAGE(D22:AH22), "")
A23: TOTAL SKOR HARIAN (Max 36) | D23: =IF(COUNT(D5:D22)>0, SUM(D5:D22), "") | E23: =IF(COUNT(E5:E22)>0, SUM(E5:E22), "") | F23: =IF(COUNT(F5:F22)>0, SUM(F5:F22), "") | G23: =IF(COUNT(G5:G22)>0, SUM(G5:G22), "") | H23: =IF(COUNT(H5:H22)>0, SUM(H5:H22), "") | I23: =IF(COUNT(I5:I22)>0, SUM(I5:I22), "") | J23: =IF(COUNT(J5:J22)>0, SUM(J5:J22), "") | K23: =IF(COUNT(K5:K22)>0, SUM(K5:K22), "") | ... AH23: =IF(COUNT(AH5:AH22)>0, SUM(AH5:AH22), "") | AI23: =IFERROR(SUM(AI5:AI22), "") -> 0
A24: RATA-RATA HARIAN (Skala 0 - 2.0) | D24: =IF(COUNT(D5:D22)>0, AVERAGE(D5:D22), "") | E24: =IF(COUNT(E5:E22)>0, AVERAGE(E5:E22), "") | F24: =IF(COUNT(F5:F22)>0, AVERAGE(F5:F22), "") | G24: =IF(COUNT(G5:G22)>0, AVERAGE(G5:G22), "") | H24: =IF(COUNT(H5:H22)>0, AVERAGE(H5:H22), "") | I24: =IF(COUNT(I5:I22)>0, AVERAGE(I5:I22), "") | J24: =IF(COUNT(J5:J22)>0, AVERAGE(J5:J22), "") | K24: =IF(COUNT(K5:K22)>0, AVERAGE(K5:K22), "") | ... AH24: =IF(COUNT(AH5:AH22)>0, AVERAGE(AH5:AH22), "") | AJ24: =IFERROR(AVERAGE(D24:AH24), "")
A25: KLASIFIKASI CAPAIAN HARIAN | D25: =IF(D24="","",IF(D24>=1.63,"BSB",IF(D24>=1.26,"BSH",IF(D24>=0.76,"MB","BB")))) | E25: =IF(E24="","",IF(E24>=1.63,"BSB",IF(E24>=1.26,"BSH",IF(E24>=0.76,"MB","BB")))) | F25: =IF(F24="","",IF(F24>=1.63,"BSB",IF(F24>=1.26,"BSH",IF(F24>=0.76,"MB","BB")))) | G25: =IF(G24="","",IF(G24>=1.63,"BSB",IF(G24>=1.26,"BSH",IF(G24>=0.76,"MB","BB")))) | H25: =IF(H24="","",IF(H24>=1.63,"BSB",IF(H24>=1.26,"BSH",IF(H24>=0.76,"MB","BB")))) | I25: =IF(I24="","",IF(I24>=1.63,"BSB",IF(I24>=1.26,"BSH",IF(I24>=0.76,"MB","BB")))) | J25: =IF(J24="","",IF(J24>=1.63,"BSB",IF(J24>=1.26,"BSH",IF(J24>=0.76,"MB","BB")))) | K25: =IF(K24="","",IF(K24>=1.63,"BSB",IF(K24>=1.26,"BSH",IF(K24>=0.76,"MB","BB")))) | ... AH25: =IF(AH24="","",IF(AH24>=1.63,"BSB",IF(AH24>=1.26,"BSH",IF(AH24>=0.76,"MB","BB")))) | AJ25: =IF(AJ24="","",IF(AJ24>=1.63,"BSB",IF(AJ24>=1.26,"BSH",IF(AJ24>=0.76,"MB","BB"))))
A28: EVALUASI BULANAN & REKOMENDASI TREATMENT GURU
A29: =IF(AJ24="","Belum ada data pengisian harian.",IF(AJ24>=1.63,"[BSB - Berkembang Sangat Baik | Skor: " & TEXT(AJ24,"0.00") & "] Treatment: Anak sangat mandiri & konsisten. Berikan proyek tantangan kepemimpinan dan pengayaan aktivitas baru.",IF(AJ24>=1.26,"[BSH - Berkembang Sesuai Harapan | Skor: " & TEXT(AJ24,"0.00") & "] Treatment: Anak berkembang sesuai usia. Pertahankan stimulasi rutin harian dan berikan pujian/apresiasi positif.",IF(AJ24>=0.76,"[MB - Mulai Berkembang | Skor: " & TEXT(AJ24,"0.00") & "] Treatment: Anak masih butuh bimbingan. Lakukan pendampingan personal (scaffolding) dan tingkatkan komunikasi rumah-sekolah.","[BB - Belum Berkembang | Skor: " & TEXT(AJ24,"0.00") & "] Treatment: Memerlukan intervensi khusus. Lakukan konseling/dialog mendalam bersama orang tua dan susun pendampingan terpandu.")))) -> Belum ada data pengisian harian.

Sheet Juni
A1: JURNAL PENILAIAN HARIAN & BULANAN AKTIVITAS ANAK TK - BULAN JUNI
A2: Nama Anak: ____________________ | Kelas: TK-A / TK-B | Tahun Ajaran: 2026/2027
A4: Pilar Evaluasi | B4: Indikator Aktivitas Harian | C4: Panduan Skor (0, 1, 2) | D4: Tgl 1 | E4: Tgl 2 | F4: Tgl 3 | G4: Tgl 4 | H4: Tgl 5 | I4: Tgl 6 | J4: Tgl 7 | K4: Tgl 8 | L4: Tgl 9 | M4: Tgl 10 | N4: Tgl 11 | O4: Tgl 12 | P4: Tgl 13 | Q4: Tgl 14 | R4: Tgl 15 | S4: Tgl 16 | T4: Tgl 17 | U4: Tgl 18 | V4: Tgl 19 | W4: Tgl 20 | X4: Tgl 21 | Y4: Tgl 22 | Z4: Tgl 23 | AA4: Tgl 24 | AB4: Tgl 25 | AC4: Tgl 26 | AD4: Tgl 27 | AE4: Tgl 28 | AF4: Tgl 29 | AG4: Tgl 30 | AH4: Total Skor | AI4: Rata-Rata Indikator
A5: Spiritual | B5: Shalat Subuh tepat waktu / belajar ikut tanpa drama | C5: 2: Tepat waktu/Ceria | 1: Kesiangan/Drama | 0: Belum mau | AH5: =IF(COUNT(D5:AG5)>0, SUM(D5:AG5), "") | AI5: =IF(COUNT(D5:AG5)>0, AVERAGE(D5:AG5), "")
A6: Spiritual | B6: Shalat Dzuhur tepat waktu / mau diajak shalat berjamaah | C6: 2: Mau diajak/Ceria | 1: Diingatkan berkali-kali | 0: Belum mau | AH6: =IF(COUNT(D6:AG6)>0, SUM(D6:AG6), "") | AI6: =IF(COUNT(D6:AG6)>0, AVERAGE(D6:AG6), "")
A7: Spiritual | B7: Shalat Ashar tepat waktu / mau diajak shalat berjamaah | C7: 2: Mau diajak/Ceria | 1: Diingatkan berkali-kali | 0: Belum mau | AH7: =IF(COUNT(D7:AG7)>0, SUM(D7:AG7), "") | AI7: =IF(COUNT(D7:AG7)>0, AVERAGE(D7:AG7), "")
A8: Spiritual | B8: Shalat Maghrib tepat waktu / mau diajak shalat berjamaah | C8: 2: Mau diajak/Ceria | 1: Diingatkan berkali-kali | 0: Belum mau | AH8: =IF(COUNT(D8:AG8)>0, SUM(D8:AG8), "") | AI8: =IF(COUNT(D8:AG8)>0, AVERAGE(D8:AG8), "")
A9: Spiritual | B9: Shalat Isya tepat waktu / mau diajak shalat berjamaah | C9: 2: Mau diajak/Ceria | 1: Diingatkan berkali-kali | 0: Belum mau | AH9: =IF(COUNT(D9:AG9)>0, SUM(D9:AG9), "") | AI9: =IF(COUNT(D9:AG9)>0, AVERAGE(D9:AG9), "")
A10: Fisik & Motorik | B10: Olahraga Pagi (senam/jalan/sepeda/fisik aktif) | C10: 2: Bergerak aktif/Ceria | 1: Hanya sebentar/Kurang semangat | 0: Malas bergerak | AH10: =IF(COUNT(D10:AG10)>0, SUM(D10:AG10), "") | AI10: =IF(COUNT(D10:AG10)>0, AVERAGE(D10:AG10), "")
A11: Fisik & Motorik | B11: Bermain Fisik Aktif Sore (bukan main gadget/HP) | C11: 2: Main luar rumah/Fisik | 1: Main di dalam rumah saja | 0: Full main HP/Gadget | AH11: =IF(COUNT(D11:AG11)>0, SUM(D11:AG11), "") | AI11: =IF(COUNT(D11:AG11)>0, AVERAGE(D11:AG11), "")
A12: Kemandirian | B12: Bangun Tidur Pagi tanpa rewel | C12: 2: Bangun ceria & segar | 1: Merengek sebentar | 0: Mengamuk/Tantrum lama | AH12: =IF(COUNT(D12:AG12)>0, SUM(D12:AG12), "") | AI12: =IF(COUNT(D12:AG12)>0, AVERAGE(D12:AG12), "")
A13: Kemandirian | B13: Perawatan Diri Pagi (mandi, sikat gigi, pakai baju sendiri) | C13: 2: Mandi & bersiap sendiri | 1: Dibantu setengahnya | 0: Dibantu total/Drama | AH13: =IF(COUNT(D13:AG13)>0, SUM(D13:AG13), "") | AI13: =IF(COUNT(D13:AG13)>0, AVERAGE(D13:AG13), "")
A14: Kemandirian | B14: Sarapan Pagi dengan tertib & mandiri | C14: 2: Habis & makan sendiri sambil duduk | 1: Disuapi sebagian | 0: Disuapi total/Sambil HP | AH14: =IF(COUNT(D14:AG14)>0, SUM(D14:AG14), "") | AI14: =IF(COUNT(D14:AG14)>0, AVERAGE(D14:AG14), "")
A15: Kemandirian | B15: Merapikan kembali mainan atau buku yang selesai digunakan | C15: 2: Inisiatif sendiri merapikan | 1: Harus disuruh berkali-kali | 0: Menolak/Ditinggal berantakan | AH15: =IF(COUNT(D15:AG15)>0, SUM(D15:AG15), "") | AI15: =IF(COUNT(D15:AG15)>0, AVERAGE(D15:AG15), "")
A16: Kemandirian | B16: Adab Pulang Rumah (ucap salam, taruh sepatu & tas sendiri) | C16: 2: Salam & taruh barang dengan rapi | 1: Harus diingatkan | 0: Barang dilempar acak-acakan | AH16: =IF(COUNT(D16:AG16)>0, SUM(D16:AG16), "") | AI16: =IF(COUNT(D16:AG16)>0, AVERAGE(D16:AG16), "")
... A22: Emosi | B22: Kejujuran & Tanggung Jawab | C22: 2: Jujur berani mengakui kesalahan | 1: Ragu-ragu/Takut jujur | 0: Berbohong | AH22: =IF(COUNT(D22:AG22)>0, SUM(D22:AG22), "") | AI22: =IF(COUNT(D22:AG22)>0, AVERAGE(D22:AG22), "")
A23: TOTAL SKOR HARIAN (Max 36) | D23: =IF(COUNT(D5:D22)>0, SUM(D5:D22), "") | E23: =IF(COUNT(E5:E22)>0, SUM(E5:E22), "") | F23: =IF(COUNT(F5:F22)>0, SUM(F5:F22), "") | G23: =IF(COUNT(G5:G22)>0, SUM(G5:G22), "") | H23: =IF(COUNT(H5:H22)>0, SUM(H5:H22), "") | I23: =IF(COUNT(I5:I22)>0, SUM(I5:I22), "") | J23: =IF(COUNT(J5:J22)>0, SUM(J5:J22), "") | K23: =IF(COUNT(K5:K22)>0, SUM(K5:K22), "") | ... AG23: =IF(COUNT(AG5:AG22)>0, SUM(AG5:AG22), "") | AH23: =IFERROR(SUM(AH5:AH22), "") -> 0
A24: RATA-RATA HARIAN (Skala 0 - 2.0) | D24: =IF(COUNT(D5:D22)>0, AVERAGE(D5:D22), "") | E24: =IF(COUNT(E5:E22)>0, AVERAGE(E5:E22), "") | F24: =IF(COUNT(F5:F22)>0, AVERAGE(F5:F22), "") | G24: =IF(COUNT(G5:G22)>0, AVERAGE(G5:G22), "") | H24: =IF(COUNT(H5:H22)>0, AVERAGE(H5:H22), "") | I24: =IF(COUNT(I5:I22)>0, AVERAGE(I5:I22), "") | J24: =IF(COUNT(J5:J22)>0, AVERAGE(J5:J22), "") | K24: =IF(COUNT(K5:K22)>0, AVERAGE(K5:K22), "") | ... AG24: =IF(COUNT(AG5:AG22)>0, AVERAGE(AG5:AG22), "") | AI24: =IFERROR(AVERAGE(D24:AG24), "")
A25: KLASIFIKASI CAPAIAN HARIAN | D25: =IF(D24="","",IF(D24>=1.63,"BSB",IF(D24>=1.26,"BSH",IF(D24>=0.76,"MB","BB")))) | E25: =IF(E24="","",IF(E24>=1.63,"BSB",IF(E24>=1.26,"BSH",IF(E24>=0.76,"MB","BB")))) | F25: =IF(F24="","",IF(F24>=1.63,"BSB",IF(F24>=1.26,"BSH",IF(F24>=0.76,"MB","BB")))) | G25: =IF(G24="","",IF(G24>=1.63,"BSB",IF(G24>=1.26,"BSH",IF(G24>=0.76,"MB","BB")))) | H25: =IF(H24="","",IF(H24>=1.63,"BSB",IF(H24>=1.26,"BSH",IF(H24>=0.76,"MB","BB")))) | I25: =IF(I24="","",IF(I24>=1.63,"BSB",IF(I24>=1.26,"BSH",IF(I24>=0.76,"MB","BB")))) | J25: =IF(J24="","",IF(J24>=1.63,"BSB",IF(J24>=1.26,"BSH",IF(J24>=0.76,"MB","BB")))) | K25: =IF(K24="","",IF(K24>=1.63,"BSB",IF(K24>=1.26,"BSH",IF(K24>=0.76,"MB","BB")))) | ... AG25: =IF(AG24="","",IF(AG24>=1.63,"BSB",IF(AG24>=1.26,"BSH",IF(AG24>=0.76,"MB","BB")))) | AI25: =IF(AI24="","",IF(AI24>=1.63,"BSB",IF(AI24>=1.26,"BSH",IF(AI24>=0.76,"MB","BB"))))
A28: EVALUASI BULANAN & REKOMENDASI TREATMENT GURU
A29: =IF(AI24="","Belum ada data pengisian harian.",IF(AI24>=1.63,"[BSB - Berkembang Sangat Baik | Skor: " & TEXT(AI24,"0.00") & "] Treatment: Anak sangat mandiri & konsisten. Berikan proyek tantangan kepemimpinan dan pengayaan aktivitas baru.",IF(AI24>=1.26,"[BSH - Berkembang Sesuai Harapan | Skor: " & TEXT(AI24,"0.00") & "] Treatment: Anak berkembang sesuai usia. Pertahankan stimulasi rutin harian dan berikan pujian/apresiasi positif.",IF(AI24>=0.76,"[MB - Mulai Berkembang | Skor: " & TEXT(AI24,"0.00") & "] Treatment: Anak masih butuh bimbingan. Lakukan pendampingan personal (scaffolding) dan tingkatkan komunikasi rumah-sekolah.","[BB - Belum Berkembang | Skor: " & TEXT(AI24,"0.00") & "] Treatment: Memerlukan intervensi khusus. Lakukan konseling/dialog mendalam bersama orang tua dan susun pendampingan terpandu.")))) -> Belum ada data pengisian harian.

Sheet Juli
A1: JURNAL PENILAIAN HARIAN & BULANAN AKTIVITAS ANAK TK - BULAN JULI
A2: Nama Anak: ____________________ | Kelas: TK-A / TK-B | Tahun Ajaran: 2026/2027
A4: Pilar Evaluasi | B4: Indikator Aktivitas Harian | C4: Panduan Skor (0, 1, 2) | D4: Tgl 1 | E4: Tgl 2 | F4: Tgl 3 | G4: Tgl 4 | H4: Tgl 5 | I4: Tgl 6 | J4: Tgl 7 | K4: Tgl 8 | L4: Tgl 9 | M4: Tgl 10 | N4: Tgl 11 | O4: Tgl 12 | P4: Tgl 13 | Q4: Tgl 14 | R4: Tgl 15 | S4: Tgl 16 | T4: Tgl 17 | U4: Tgl 18 | V4: Tgl 19 | W4: Tgl 20 | X4: Tgl 21 | Y4: Tgl 22 | Z4: Tgl 23 | AA4: Tgl 24 | AB4: Tgl 25 | AC4: Tgl 26 | AD4: Tgl 27 | AE4: Tgl 28 | AF4: Tgl 29 | AG4: Tgl 30 | AH4: Tgl 31 | AI4: Total Skor | AJ4: Rata-Rata Indikator
A5: Spiritual | B5: Shalat Subuh tepat waktu / belajar ikut tanpa drama | C5: 2: Tepat waktu/Ceria | 1: Kesiangan/Drama | 0: Belum mau | AI5: =IF(COUNT(D5:AH5)>0, SUM(D5:AH5), "") | AJ5: =IF(COUNT(D5:AH5)>0, AVERAGE(D5:AH5), "")
A6: Spiritual | B6: Shalat Dzuhur tepat waktu / mau diajak shalat berjamaah | C6: 2: Mau diajak/Ceria | 1: Diingatkan berkali-kali | 0: Belum mau | AI6: =IF(COUNT(D6:AH6)>0, SUM(D6:AH6), "") | AJ6: =IF(COUNT(D6:AH6)>0, AVERAGE(D6:AH6), "")
A7: Spiritual | B7: Shalat Ashar tepat waktu / mau diajak shalat berjamaah | C7: 2: Mau diajak/Ceria | 1: Diingatkan berkali-kali | 0: Belum mau | AI7: =IF(COUNT(D7:AH7)>0, SUM(D7:AH7), "") | AJ7: =IF(COUNT(D7:AH7)>0, AVERAGE(D7:AH7), "")
A8: Spiritual | B8: Shalat Maghrib tepat waktu / mau diajak shalat berjamaah | C8: 2: Mau diajak/Ceria | 1: Diingatkan berkali-kali | 0: Belum mau | AI8: =IF(COUNT(D8:AH8)>0, SUM(D8:AH8), "") | AJ8: =IF(COUNT(D8:AH8)>0, AVERAGE(D8:AH8), "")
A9: Spiritual | B9: Shalat Isya tepat waktu / mau diajak shalat berjamaah | C9: 2: Mau diajak/Ceria | 1: Diingatkan berkali-kali | 0: Belum mau | AI9: =IF(COUNT(D9:AH9)>0, SUM(D9:AH9), "") | AJ9: =IF(COUNT(D9:AH9)>0, AVERAGE(D9:AH9), "")
A10: Fisik & Motorik | B10: Olahraga Pagi (senam/jalan/sepeda/fisik aktif) | C10: 2: Bergerak aktif/Ceria | 1: Hanya sebentar/Kurang semangat | 0: Malas bergerak | AI10: =IF(COUNT(D10:AH10)>0, SUM(D10:AH10), "") | AJ10: =IF(COUNT(D10:AH10)>0, AVERAGE(D10:AH10), "")
A11: Fisik & Motorik | B11: Bermain Fisik Aktif Sore (bukan main gadget/HP) | C11: 2: Main luar rumah/Fisik | 1: Main di dalam rumah saja | 0: Full main HP/Gadget | AI11: =IF(COUNT(D11:AH11)>0, SUM(D11:AH11), "") | AJ11: =IF(COUNT(D11:AH11)>0, AVERAGE(D11:AH11), "")
A12: Kemandirian | B12: Bangun Tidur Pagi tanpa rewel | C12: 2: Bangun ceria & segar | 1: Merengek sebentar | 0: Mengamuk/Tantrum lama | AI12: =IF(COUNT(D12:AH12)>0, SUM(D12:AH12), "") | AJ12: =IF(COUNT(D12:AH12)>0, AVERAGE(D12:AH12), "")
A13: Kemandirian | B13: Perawatan Diri Pagi (mandi, sikat gigi, pakai baju sendiri) | C13: 2: Mandi & bersiap sendiri | 1: Dibantu setengahnya | 0: Dibantu total/Drama | AI13: =IF(COUNT(D13:AH13)>0, SUM(D13:AH13), "") | AJ13: =IF(COUNT(D13:AH13)>0, AVERAGE(D13:AH13), "")
A14: Kemandirian | B14: Sarapan Pagi dengan tertib & mandiri | C14: 2: Habis & makan sendiri sambil duduk | 1: Disuapi sebagian | 0: Disuapi total/Sambil HP | AI14: =IF(COUNT(D14:AH14)>0, SUM(D14:AH14), "") | AJ14: =IF(COUNT(D14:AH14)>0, AVERAGE(D14:AH14), "")
A15: Kemandirian | B15: Merapikan kembali mainan atau buku yang selesai digunakan | C15: 2: Inisiatif sendiri merapikan | 1: Harus disuruh berkali-kali | 0: Menolak/Ditinggal berantakan | AI15: =IF(COUNT(D15:AH15)>0, SUM(D15:AH15), "") | AJ15: =IF(COUNT(D15:AH15)>0, AVERAGE(D15:AH15), "")
A16: Kemandirian | B16: Adab Pulang Rumah (ucap salam, taruh sepatu & tas sendiri) | C16: 2: Salam & taruh barang dengan rapi | 1: Harus diingatkan | 0: Barang dilempar acak-acakan | AI16: =IF(COUNT(D16:AH16)>0, SUM(D16:AH16), "") | AJ16: =IF(COUNT(D16:AH16)>0, AVERAGE(D16:AH16), "")
... A22: Emosi | B22: Kejujuran & Tanggung Jawab | C22: 2: Jujur berani mengakui kesalahan | 1: Ragu-ragu/Takut jujur | 0: Berbohong | AI22: =IF(COUNT(D22:AH22)>0, SUM(D22:AH22), "") | AJ22: =IF(COUNT(D22:AH22)>0, AVERAGE(D22:AH22), "")
A23: TOTAL SKOR HARIAN (Max 36) | D23: =IF(COUNT(D5:D22)>0, SUM(D5:D22), "") | E23: =IF(COUNT(E5:E22)>0, SUM(E5:E22), "") | F23: =IF(COUNT(F5:F22)>0, SUM(F5:F22), "") | G23: =IF(COUNT(G5:G22)>0, SUM(G5:G22), "") | H23: =IF(COUNT(H5:H22)>0, SUM(H5:H22), "") | I23: =IF(COUNT(I5:I22)>0, SUM(I5:I22), "") | J23: =IF(COUNT(J5:J22)>0, SUM(J5:J22), "") | K23: =IF(COUNT(K5:K22)>0, SUM(K5:K22), "") | ... AH23: =IF(COUNT(AH5:AH22)>0, SUM(AH5:AH22), "") | AI23: =IFERROR(SUM(AI5:AI22), "") -> 0
A24: RATA-RATA HARIAN (Skala 0 - 2.0) | D24: =IF(COUNT(D5:D22)>0, AVERAGE(D5:D22), "") | E24: =IF(COUNT(E5:E22)>0, AVERAGE(E5:E22), "") | F24: =IF(COUNT(F5:F22)>0, AVERAGE(F5:F22), "") | G24: =IF(COUNT(G5:G22)>0, AVERAGE(G5:G22), "") | H24: =IF(COUNT(H5:H22)>0, AVERAGE(H5:H22), "") | I24: =IF(COUNT(I5:I22)>0, AVERAGE(I5:I22), "") | J24: =IF(COUNT(J5:J22)>0, AVERAGE(J5:J22), "") | K24: =IF(COUNT(K5:K22)>0, AVERAGE(K5:K22), "") | ... AH24: =IF(COUNT(AH5:AH22)>0, AVERAGE(AH5:AH22), "") | AJ24: =IFERROR(AVERAGE(D24:AH24), "")
A25: KLASIFIKASI CAPAIAN HARIAN | D25: =IF(D24="","",IF(D24>=1.63,"BSB",IF(D24>=1.26,"BSH",IF(D24>=0.76,"MB","BB")))) | E25: =IF(E24="","",IF(E24>=1.63,"BSB",IF(E24>=1.26,"BSH",IF(E24>=0.76,"MB","BB")))) | F25: =IF(F24="","",IF(F24>=1.63,"BSB",IF(F24>=1.26,"BSH",IF(F24>=0.76,"MB","BB")))) | G25: =IF(G24="","",IF(G24>=1.63,"BSB",IF(G24>=1.26,"BSH",IF(G24>=0.76,"MB","BB")))) | H25: =IF(H24="","",IF(H24>=1.63,"BSB",IF(H24>=1.26,"BSH",IF(H24>=0.76,"MB","BB")))) | I25: =IF(I24="","",IF(I24>=1.63,"BSB",IF(I24>=1.26,"BSH",IF(I24>=0.76,"MB","BB")))) | J25: =IF(J24="","",IF(J24>=1.63,"BSB",IF(J24>=1.26,"BSH",IF(J24>=0.76,"MB","BB")))) | K25: =IF(K24="","",IF(K24>=1.63,"BSB",IF(K24>=1.26,"BSH",IF(K24>=0.76,"MB","BB")))) | ... AH25: =IF(AH24="","",IF(AH24>=1.63,"BSB",IF(AH24>=1.26,"BSH",IF(AH24>=0.76,"MB","BB")))) | AJ25: =IF(AJ24="","",IF(AJ24>=1.63,"BSB",IF(AJ24>=1.26,"BSH",IF(AJ24>=0.76,"MB","BB"))))
A28: EVALUASI BULANAN & REKOMENDASI TREATMENT GURU
A29: =IF(AJ24="","Belum ada data pengisian harian.",IF(AJ24>=1.63,"[BSB - Berkembang Sangat Baik | Skor: " & TEXT(AJ24,"0.00") & "] Treatment: Anak sangat mandiri & konsisten. Berikan proyek tantangan kepemimpinan dan pengayaan aktivitas baru.",IF(AJ24>=1.26,"[BSH - Berkembang Sesuai Harapan | Skor: " & TEXT(AJ24,"0.00") & "] Treatment: Anak berkembang sesuai usia. Pertahankan stimulasi rutin harian dan berikan pujian/apresiasi positif.",IF(AJ24>=0.76,"[MB - Mulai Berkembang | Skor: " & TEXT(AJ24,"0.00") & "] Treatment: Anak masih butuh bimbingan. Lakukan pendampingan personal (scaffolding) dan tingkatkan komunikasi rumah-sekolah.","[BB - Belum Berkembang | Skor: " & TEXT(AJ24,"0.00") & "] Treatment: Memerlukan intervensi khusus. Lakukan konseling/dialog mendalam bersama orang tua dan susun pendampingan terpandu.")))) -> Belum ada data pengisian harian.

Sheet Agustus
A1: JURNAL PENILAIAN HARIAN & BULANAN AKTIVITAS ANAK TK - BULAN AGUSTUS
A2: Nama Anak: ____________________ | Kelas: TK-A / TK-B | Tahun Ajaran: 2026/2027
A4: Pilar Evaluasi | B4: Indikator Aktivitas Harian | C4: Panduan Skor (0, 1, 2) | D4: Tgl 1 | E4: Tgl 2 | F4: Tgl 3 | G4: Tgl 4 | H4: Tgl 5 | I4: Tgl 6 | J4: Tgl 7 | K4: Tgl 8 | L4: Tgl 9 | M4: Tgl 10 | N4: Tgl 11 | O4: Tgl 12 | P4: Tgl 13 | Q4: Tgl 14 | R4: Tgl 15 | S4: Tgl 16 | T4: Tgl 17 | U4: Tgl 18 | V4: Tgl 19 | W4: Tgl 20 | X4: Tgl 21 | Y4: Tgl 22 | Z4: Tgl 23 | AA4: Tgl 24 | AB4: Tgl 25 | AC4: Tgl 26 | AD4: Tgl 27 | AE4: Tgl 28 | AF4: Tgl 29 | AG4: Tgl 30 | AH4: Tgl 31 | AI4: Total Skor | AJ4: Rata-Rata Indikator
A5: Spiritual | B5: Shalat Subuh tepat waktu / belajar ikut tanpa drama | C5: 2: Tepat waktu/Ceria | 1: Kesiangan/Drama | 0: Belum mau | AI5: =IF(COUNT(D5:AH5)>0, SUM(D5:AH5), "") | AJ5: =IF(COUNT(D5:AH5)>0, AVERAGE(D5:AH5), "")
A6: Spiritual | B6: Shalat Dzuhur tepat waktu / mau diajak shalat berjamaah | C6: 2: Mau diajak/Ceria | 1: Diingatkan berkali-kali | 0: Belum mau | AI6: =IF(COUNT(D6:AH6)>0, SUM(D6:AH6), "") | AJ6: =IF(COUNT(D6:AH6)>0, AVERAGE(D6:AH6), "")
A7: Spiritual | B7: Shalat Ashar tepat waktu / mau diajak shalat berjamaah | C7: 2: Mau diajak/Ceria | 1: Diingatkan berkali-kali | 0: Belum mau | AI7: =IF(COUNT(D7:AH7)>0, SUM(D7:AH7), "") | AJ7: =IF(COUNT(D7:AH7)>0, AVERAGE(D7:AH7), "")
A8: Spiritual | B8: Shalat Maghrib tepat waktu / mau diajak shalat berjamaah | C8: 2: Mau diajak/Ceria | 1: Diingatkan berkali-kali | 0: Belum mau | AI8: =IF(COUNT(D8:AH8)>0, SUM(D8:AH8), "") | AJ8: =IF(COUNT(D8:AH8)>0, AVERAGE(D8:AH8), "")
